<?xml version="1.0" encoding="utf-8"?>
<!-- This URDF was automatically created by SolidWorks to URDF Exporter! Originally created by Stephen Brawner (brawner@gmail.com) 
     Commit Version: 1.5.1-0-g916b5db  Build Version: 1.5.7152.31018
     For more information, please see http://wiki.ros.org/sw_urdf_exporter -->
<robot
  name="total_1" xmlns:xacro="http://ros.org/wiki/xacro">
  <link
    name="base_link">
    <inertial>
      <origin
        xyz="0.000111425128212578 -0.000416658277615577 0.0127089714853932"
        rpy="0 0 0" />
      <mass
        value="0.135990258934414" />
      <inertia
        ixx="7.47793671419353E-05"
        ixy="2.48153910110134E-08"
        ixz="7.91907519846991E-08"
        iyy="7.83839116184578E-05"
        iyz="2.76986466267398E-06"
        izz="5.42867191438555E-05" />
    </inertial>
    <visual>
      <origin
        xyz="0 0 0"
        rpy="0 0 0" />
      <geometry>
        <mesh
          filename="package://total_1/meshes/base_link.STL" />
      </geometry>
      <material
        name="">
        <color
          rgba="0.792156862745098 0.819607843137255 0.933333333333333 1" />
      </material>
    </visual>
    <collision>
      <origin
        xyz="0 0 0"
        rpy="0 0 0" />
      <geometry>
        <mesh
          filename="package://total_1/meshes/base_link.STL" />
      </geometry>
    </collision>
  </link>
  <link
    name="Link_1">
    <inertial>
      <origin
        xyz="-0.00014027069834739 0.0235846779807264 -0.108590415329906"
        rpy="0 0 0" />
      <mass
        value="0.182834423024122" />
      <inertia
        ixx="0.000341979944804599"
        ixy="1.4254689237441E-08"
        ixz="-4.00330233263361E-07"
        iyy="0.000321161427222935"
        iyz="4.92378170168113E-06"
        izz="9.22926257159133E-05" />
    </inertial>
    <visual>
      <origin
        xyz="0 0 0"
        rpy="0 0 0" />
      <geometry>
        <mesh
          filename="package://total_1/meshes/Link_1.STL" />
      </geometry>
      <material
        name="">
        <color
          rgba="0.792156862745098 0.819607843137255 0.933333333333333 1" />
      </material>
    </visual>
    <collision>
      <origin
        xyz="0 0 0"
        rpy="0 0 0" />
      <geometry>
        <mesh
          filename="package://total_1/meshes/Link_1.STL" />
      </geometry>
    </collision>
  </link>
  <joint
    name="Joint_1"
    type="revolute">
    <origin
      xyz="0 -0.0245 0"
      rpy="0 0 0" />
    <parent
      link="base_link" />
    <child
      link="Link_1" />
    <axis
      xyz="0 -1 0" />
    <limit
      lower="-1.57"
      upper="1.57"
      effort="0"
      velocity="0.5" />
  </joint>
  <link
    name="Link_2">
    <inertial>
      <origin
        xyz="-0.000140270698346693 0.0235846779807248 -0.1085904153299"
        rpy="0 0 0" />
      <mass
        value="0.182834423024137" />
      <inertia
        ixx="0.000341979944804709"
        ixy="1.4254689241052E-08"
        ixz="-4.00330233269869E-07"
        iyy="0.00032116142722304"
        iyz="4.92378170170686E-06"
        izz="9.22926257159223E-05" />
    </inertial>
    <visual>
      <origin
        xyz="0 0 0"
        rpy="0 0 0" />
      <geometry>
        <mesh
          filename="package://total_1/meshes/Link_2.STL" />
      </geometry>
      <material
        name="">
        <color
          rgba="0.792156862745098 0.819607843137255 0.933333333333333 1" />
      </material>
    </visual>
    <collision>
      <origin
        xyz="0 0 0"
        rpy="0 0 0" />
      <geometry>
        <mesh
          filename="package://total_1/meshes/Link_2.STL" />
      </geometry>
    </collision>
  </link>
  <joint
    name="Joint_2"
    type="revolute">
    <origin
      xyz="-0.0003 -0.0009 -0.14"
      rpy="0 0 0" />
    <parent
      link="Link_1" />
    <child
      link="Link_2" />
    <axis
      xyz="0 -1 0" />
    <limit
      lower="-2.35"
      upper="2.35"
      effort="0"
      velocity="0.5" />
  </joint>
  <link
    name="Link_3">
    <inertial>
      <origin
        xyz="-1.17571954342394E-10 0.0235985338515883 -0.0495941266535813"
        rpy="0 0 0" />
      <mass
        value="0.0925957244484133" />
      <inertia
        ixx="7.14445352639827E-05"
        ixy="-9.15271146295221E-11"
        ixz="5.3990769860352E-13"
        iyy="5.25341169702674E-05"
        iyz="1.81909699538905E-06"
        izz="4.78366963095397E-05" />
    </inertial>
    <visual>
      <origin
        xyz="0 0 0"
        rpy="0 0 0" />
      <geometry>
        <mesh
          filename="package://total_1/meshes/Link_3.STL" />
      </geometry>
      <material
        name="">
        <color
          rgba="0.792156862745098 0.819607843137255 0.933333333333333 1" />
      </material>
    </visual>
    <collision>
      <origin
        xyz="0 0 0"
        rpy="0 0 0" />
      <geometry>
        <mesh
          filename="package://total_1/meshes/Link_3.STL" />
      </geometry>
    </collision>
  </link>
  <joint
    name="Joint_3"
    type="revolute">
    <origin
      xyz="-0.0003 -0.0009 -0.14"
      rpy="0 0 0" />
    <parent
      link="Link_2" />
    <child
      link="Link_3" />
    <axis
      xyz="0 -1 0" />
    <limit
      lower="-2.04"
      upper="2.04"
      effort="0"
      velocity="0.5" />
  </joint>
</robot>